 * Starting OpenBSD Secure Shell server sshd
   ...done.
INFO:circe.py:Using base script preagg.py
DEBUG:circe.py:starting the input monitoring process
DEBUG:circe.py:starting the output monitoring process
4
INFO:circe.py:runtime_stat:{"task_name": "circe", "event": "new_input_file", "filename": "score4b_preagg4_2jobth3#99904830-3#03147318-3#62868225-3#47677912", "unix_time": 1620589377.4669163}
INFO:ccdag_utils.py:runtime_stat:{"task_name": "preagg4", "event": "queue_start_process", "filename": "score4b_preagg4_2jobth3#99904830-3#03147318-3#62868225-3#47677912", "unix_time": 1620589377.5819871}
Exception in thread Thread-3:
Traceback (most recent call last):
  File "/usr/lib/python3/dist-packages/urllib3/connection.py", line 144, in _new_conn
    (self.host, self.port), self.timeout, **extra_kw)
  File "/usr/lib/python3/dist-packages/urllib3/util/connection.py", line 83, in create_connection
    raise err
  File "/usr/lib/python3/dist-packages/urllib3/util/connection.py", line 73, in create_connection
    sock.connect(sa)
ConnectionRefusedError: [Errno 111] Connection refused

During handling of the above exception, another exception occurred:

Traceback (most recent call last):
  File "/usr/lib/python3/dist-packages/urllib3/connectionpool.py", line 601, in urlopen
    chunked=chunked)
  File "/usr/lib/python3/dist-packages/urllib3/connectionpool.py", line 357, in _make_request
    conn.request(method, url, **httplib_request_kw)
  File "/usr/lib/python3.6/http/client.py", line 1281, in request
    self._send_request(method, url, body, headers, encode_chunked)
  File "/usr/lib/python3.6/http/client.py", line 1327, in _send_request
    self.endheaders(body, encode_chunked=encode_chunked)
  File "/usr/lib/python3.6/http/client.py", line 1276, in endheaders
    self._send_output(message_body, encode_chunked=encode_chunked)
  File "/usr/lib/python3.6/http/client.py", line 1042, in _send_output
    self.send(msg)
  File "/usr/lib/python3.6/http/client.py", line 980, in send
    self.connect()
  File "/usr/lib/python3/dist-packages/urllib3/connection.py", line 169, in connect
    conn = self._new_conn()
  File "/usr/lib/python3/dist-packages/urllib3/connection.py", line 153, in _new_conn
    self, "Failed to establish a new connection: %s" % e)
urllib3.exceptions.NewConnectionError: <urllib3.connection.HTTPConnection object at 0x7fa7e2ede470>: Failed to establish a new connection: [Errno 111] Connection refused

During handling of the above exception, another exception occurred:

Traceback (most recent call last):
  File "/usr/lib/python3/dist-packages/requests/adapters.py", line 440, in send
    timeout=timeout
  File "/usr/lib/python3/dist-packages/urllib3/connectionpool.py", line 639, in urlopen
    _stacktrace=sys.exc_info()[2])
  File "/usr/lib/python3/dist-packages/urllib3/util/retry.py", line 398, in increment
    raise MaxRetryError(_pool, url, error or ResponseError(cause))
urllib3.exceptions.MaxRetryError: HTTPConnectionPool(host='10.100.92.70', port=6100): Max retries exceeded with url: /post-dict (Caused by NewConnectionError('<urllib3.connection.HTTPConnection object at 0x7fa7e2ede470>: Failed to establish a new connection: [Errno 111] Connection refused',))

During handling of the above exception, another exception occurred:

Traceback (most recent call last):
  File "/jupiter/build/app_specific_files/preagg.py", line 96, in task
    response =  requests.post(url, headers = hdr,data = json.dumps(payload))
  File "/usr/lib/python3/dist-packages/requests/api.py", line 112, in post
    return request('post', url, data=data, json=json, **kwargs)
  File "/usr/lib/python3/dist-packages/requests/api.py", line 58, in request
    return session.request(method=method, url=url, **kwargs)
  File "/usr/lib/python3/dist-packages/requests/sessions.py", line 520, in request
    resp = self.send(prep, **send_kwargs)
  File "/usr/lib/python3/dist-packages/requests/sessions.py", line 630, in send
    r = adapter.send(request, **kwargs)
  File "/usr/lib/python3/dist-packages/requests/adapters.py", line 508, in send
    raise ConnectionError(e, request=request)
requests.exceptions.ConnectionError: HTTPConnectionPool(host='10.100.92.70', port=6100): Max retries exceeded with url: /post-dict (Caused by NewConnectionError('<urllib3.connection.HTTPConnection object at 0x7fa7e2ede470>: Failed to establish a new connection: [Errno 111] Connection refused',))

During handling of the above exception, another exception occurred:

Traceback (most recent call last):
  File "/usr/lib/python3.6/threading.py", line 916, in _bootstrap_inner
    self.run()
  File "/usr/lib/python3.6/threading.py", line 864, in run
    self._target(*self._args, **self._kwargs)
  File "/jupiter/build/app_specific_files/preagg.py", line 105, in task
    job_dict = {'2':[sample1[0],sample2[0]]}
IndexError: list index out of range

INFO:circe.py:runtime_stat:{"task_name": "circe", "event": "new_input_file", "filename": "score4c_preagg4_2jobth3#99904830-3#03147318-3#62868225-3#47677912", "unix_time": 1620589378.7285788}
INFO:circe.py:runtime_stat:{"task_name": "circe", "event": "new_input_file", "filename": "score4a_preagg4_2jobth3#99904830-3#03147318-3#62868225-3#47677912", "unix_time": 1620589387.2874527}
INFO:circe.py:runtime_stat:{"task_name": "circe", "event": "new_input_file", "filename": "score4b_preagg4_2jobth3#20778576-3#83976113-3#92221545-3#11190924", "unix_time": 1620589433.003221}
INFO:circe.py:runtime_stat:{"task_name": "circe", "event": "new_input_file", "filename": "score4c_preagg4_2jobth3#20778576-3#83976113-3#92221545-3#11190924", "unix_time": 1620589434.292474}
INFO:circe.py:runtime_stat:{"task_name": "circe", "event": "new_input_file", "filename": "score4a_preagg4_2jobth3#20778576-3#83976113-3#92221545-3#11190924", "unix_time": 1620589441.787698}
INFO:circe.py:runtime_stat:{"task_name": "circe", "event": "new_input_file", "filename": "score4b_preagg4_2jobth3#57800441-3#79663040-3#52067035-3#77843637", "unix_time": 1620589464.5867023}
INFO:circe.py:runtime_stat:{"task_name": "circe", "event": "new_input_file", "filename": "score4c_preagg4_2jobth3#57800441-3#79663040-3#52067035-3#77843637", "unix_time": 1620589464.9162636}
INFO:circe.py:runtime_stat:{"task_name": "circe", "event": "new_input_file", "filename": "score4a_preagg4_2jobth3#57800441-3#79663040-3#52067035-3#77843637", "unix_time": 1620589473.347186}
INFO:circe.py:runtime_stat:{"task_name": "circe", "event": "new_input_file", "filename": "score4b_preagg4_1jobth3#46923189-3#82551562-3#23226684-3#39694868", "unix_time": 1620589493.11014}
INFO:circe.py:runtime_stat:{"task_name": "circe", "event": "new_input_file", "filename": "score4c_preagg4_1jobth3#46923189-3#82551562-3#23226684-3#39694868", "unix_time": 1620589494.4439657}
INFO:circe.py:runtime_stat:{"task_name": "circe", "event": "new_input_file", "filename": "score4a_preagg4_1jobth3#46923189-3#82551562-3#23226684-3#39694868", "unix_time": 1620589501.755062}
INFO:circe.py:runtime_stat:{"task_name": "circe", "event": "new_input_file", "filename": "score4b_preagg4_2jobth3#44050744-3#92621446-3#23472243-3#33596729", "unix_time": 1620589739.8887374}
INFO:circe.py:runtime_stat:{"task_name": "circe", "event": "new_input_file", "filename": "score4c_preagg4_2jobth3#44050744-3#92621446-3#23472243-3#33596729", "unix_time": 1620589741.232426}
INFO:circe.py:runtime_stat:{"task_name": "circe", "event": "new_input_file", "filename": "score4a_preagg4_2jobth3#44050744-3#92621446-3#23472243-3#33596729", "unix_time": 1620589748.5141227}
INFO:circe.py:runtime_stat:{"task_name": "circe", "event": "new_input_file", "filename": "score4b_preagg4_3jobth3#29556548-3#61856345-3#13379051-3#38760569", "unix_time": 1620589789.4858704}
INFO:circe.py:runtime_stat:{"task_name": "circe", "event": "new_input_file", "filename": "score4c_preagg4_3jobth3#29556548-3#61856345-3#13379051-3#38760569", "unix_time": 1620589789.7921603}
INFO:circe.py:runtime_stat:{"task_name": "circe", "event": "new_input_file", "filename": "score4a_preagg4_3jobth3#29556548-3#61856345-3#13379051-3#38760569", "unix_time": 1620589798.0487916}
INFO:circe.py:runtime_stat:{"task_name": "circe", "event": "new_input_file", "filename": "score4b_preagg4_4jobth3#42586684-3#15263256-3#59250357-3#48410240", "unix_time": 1620589851.070258}
INFO:circe.py:runtime_stat:{"task_name": "circe", "event": "new_input_file", "filename": "score4c_preagg4_4jobth3#42586684-3#15263256-3#59250357-3#48410240", "unix_time": 1620589852.4363801}
INFO:circe.py:runtime_stat:{"task_name": "circe", "event": "new_input_file", "filename": "score4a_preagg4_4jobth3#42586684-3#15263256-3#59250357-3#48410240", "unix_time": 1620589860.6385248}
INFO:circe.py:runtime_stat:{"task_name": "circe", "event": "new_input_file", "filename": "score4b_preagg4_5jobth3#55873110-3#82473421-3#61387354-3#72357474", "unix_time": 1620589896.7058995}
INFO:circe.py:runtime_stat:{"task_name": "circe", "event": "new_input_file", "filename": "score4c_preagg4_5jobth3#55873110-3#82473421-3#61387354-3#72357474", "unix_time": 1620589897.9353163}
INFO:circe.py:runtime_stat:{"task_name": "circe", "event": "new_input_file", "filename": "score4a_preagg4_5jobth3#55873110-3#82473421-3#61387354-3#72357474", "unix_time": 1620589905.1232727}
